I'm sorry, but an uncaught exception occurred.

While running game code:
  File "game/script.rpy", line 52, in script call
    call firststory from _call_firststory
  File "game/script.rpy", line 134, in script
    b "I agree hahaha..  "
Exception: DynamicImage u'[ex[1][2]]': could not find image. (u'images/char/male/hair/h5.png')

-- Full Traceback ------------------------------------------------------------

Full traceback:
  File "game/script.rpy", line 52, in script call
    call firststory from _call_firststory
  File "game/script.rpy", line 134, in script
    b "I agree hahaha..  "
  File "renpy/ast.py", line 715, in execute
    renpy.exports.say(who, what, *args, **kwargs)
  File "renpy/exports.py", line 1393, in say
    who(what, *args, **kwargs)
  File "renpy/character.py", line 1205, in __call__
    self.do_display(who, what, cb_args=self.cb_args, dtt=dtt, **display_args)
  File "renpy/character.py", line 871, in do_display
    **display_args)
  File "renpy/character.py", line 621, in display_say
    rv = renpy.ui.interact(mouse='say', type=type, roll_forward=roll_forward)
  File "renpy/ui.py", line 298, in interact
    rv = renpy.game.interface.interact(roll_forward=roll_forward, **kwargs)
  File "renpy/display/core.py", line 3101, in interact
    repeat, rv = self.interact_core(preloads=preloads, trans_pause=trans_pause, pause=pause, pause_start=pause_start, **kwargs)
  File "renpy/display/core.py", line 3512, in interact_core
    root_widget.visit_all(lambda i : i.per_interact())
  File "renpy/display/core.py", line 567, in visit_all
    d.visit_all(callback, seen)
  File "renpy/display/core.py", line 567, in visit_all
    d.visit_all(callback, seen)
  File "renpy/display/core.py", line 567, in visit_all
    d.visit_all(callback, seen)
  File "renpy/display/core.py", line 567, in visit_all
    d.visit_all(callback, seen)
  File "renpy/display/core.py", line 567, in visit_all
    d.visit_all(callback, seen)
  File "renpy/display/core.py", line 567, in visit_all
    d.visit_all(callback, seen)
  File "renpy/display/core.py", line 567, in visit_all
    d.visit_all(callback, seen)
  File "renpy/display/core.py", line 567, in visit_all
    d.visit_all(callback, seen)
  File "renpy/display/core.py", line 567, in visit_all
    d.visit_all(callback, seen)
  File "renpy/display/core.py", line 557, in visit_all
    for d in self.visit():
  File "renpy/display/image.py", line 743, in visit
    self.find_target()
  File "renpy/display/image.py", line 652, in find_target
    raise Exception(error)
Exception: DynamicImage u'[ex[1][2]]': could not find image. (u'images/char/male/hair/h5.png')

Windows-10-10.0.19041
Ren'Py 7.4.4.1439
test 1.0
Wed Aug  4 22:18:18 2021
